[2025-07-28T14:27:58.433+0000] {taskinstance.py:1159} INFO - Dependencies all met for dep_context=non-requeueable deps ti=<TaskInstance: orders_dag.fetch_and_load_orders manual__2025-07-28T14:27:54.502949+00:00 [queued]>
[2025-07-28T14:27:58.499+0000] {taskinstance.py:1159} INFO - Dependencies all met for dep_context=requeueable deps ti=<TaskInstance: orders_dag.fetch_and_load_orders manual__2025-07-28T14:27:54.502949+00:00 [queued]>
[2025-07-28T14:27:58.500+0000] {taskinstance.py:1361} INFO - Starting attempt 1 of 1
[2025-07-28T14:27:58.587+0000] {taskinstance.py:1382} INFO - Executing <Task(PythonOperator): fetch_and_load_orders> on 2025-07-28 14:27:54.502949+00:00
[2025-07-28T14:27:58.620+0000] {standard_task_runner.py:57} INFO - Started process 10070 to run task
[2025-07-28T14:27:58.654+0000] {standard_task_runner.py:84} INFO - Running: ['***', 'tasks', 'run', 'orders_dag', 'fetch_and_load_orders', 'manual__2025-07-28T14:27:54.502949+00:00', '--job-id', '13', '--raw', '--subdir', 'DAGS_FOLDER/orders_dag.py', '--cfg-path', '/tmp/tmpg100qzen']
[2025-07-28T14:27:58.676+0000] {standard_task_runner.py:85} INFO - Job 13: Subtask fetch_and_load_orders
[2025-07-28T14:27:58.889+0000] {task_command.py:416} INFO - Running <TaskInstance: orders_dag.fetch_and_load_orders manual__2025-07-28T14:27:54.502949+00:00 [running]> on host 979e7d3a451f
[2025-07-28T14:27:59.108+0000] {taskinstance.py:1662} INFO - Exporting env vars: AIRFLOW_CTX_DAG_OWNER='***' AIRFLOW_CTX_DAG_ID='orders_dag' AIRFLOW_CTX_TASK_ID='fetch_and_load_orders' AIRFLOW_CTX_EXECUTION_DATE='2025-07-28T14:27:54.502949+00:00' AIRFLOW_CTX_TRY_NUMBER='1' AIRFLOW_CTX_DAG_RUN_ID='manual__2025-07-28T14:27:54.502949+00:00'
[2025-07-28T14:27:59.115+0000] {logging_mixin.py:151} INFO - ðŸš€ Starting data fetch from API...
[2025-07-28T14:27:59.289+0000] {logging_mixin.py:151} INFO - ðŸ”Ž Status Code: 200
[2025-07-28T14:27:59.294+0000] {logging_mixin.py:151} INFO - ðŸ”Ž Raw Response: [{"order_id":"00125cb692d04887809806618a2a145f","user_name":"7ac26eac431c6848694a2de6f0327524","order_status":"delivered","order_date":"3/23/2017 12:21","order_approved_date":"3/23/2017 13:05","pickup_date":"3/27/2017 8:58","delivered_date":"4/7/2017 15:32","estimated_time_delivery":"4/20/2017 0:00"
[2025-07-28T14:27:59.309+0000] {logging_mixin.py:151} INFO - âœ… Successfully parsed JSON. Total Orders: 602
[2025-07-28T14:27:59.419+0000] {taskinstance.py:1937} ERROR - Task failed with exception
Traceback (most recent call last):
  File "/home/airflow/.local/lib/python3.8/site-packages/mysql/connector/connection_cext.py", line 302, in _open_connection
    self._cmysql.connect(**cnx_kwargs)
_mysql_connector.MySQLInterfaceError: Unknown MySQL server host 'mysql' (-3)

The above exception was the direct cause of the following exception:

Traceback (most recent call last):
  File "/home/airflow/.local/lib/python3.8/site-packages/airflow/operators/python.py", line 192, in execute
    return_value = self.execute_callable()
  File "/home/airflow/.local/lib/python3.8/site-packages/airflow/operators/python.py", line 209, in execute_callable
    return self.python_callable(*self.op_args, **self.op_kwargs)
  File "/opt/airflow/dags/orders_dag.py", line 41, in fetch_and_load_orders
    conn = mysql.connector.connect(**DB_CONFIG)
  File "/home/airflow/.local/lib/python3.8/site-packages/mysql/connector/pooling.py", line 293, in connect
    return CMySQLConnection(*args, **kwargs)
  File "/home/airflow/.local/lib/python3.8/site-packages/mysql/connector/connection_cext.py", line 128, in __init__
    self.connect(**kwargs)
  File "/home/airflow/.local/lib/python3.8/site-packages/mysql/connector/abstracts.py", line 1217, in connect
    self._open_connection()
  File "/home/airflow/.local/lib/python3.8/site-packages/mysql/connector/connection_cext.py", line 307, in _open_connection
    raise get_mysql_exception(
mysql.connector.errors.DatabaseError: 2005 (HY000): Unknown MySQL server host 'mysql' (-3)
[2025-07-28T14:27:59.464+0000] {taskinstance.py:1400} INFO - Marking task as FAILED. dag_id=orders_dag, task_id=fetch_and_load_orders, execution_date=20250728T142754, start_date=20250728T142758, end_date=20250728T142759
[2025-07-28T14:27:59.530+0000] {standard_task_runner.py:104} ERROR - Failed to execute job 13 for task fetch_and_load_orders (2005 (HY000): Unknown MySQL server host 'mysql' (-3); 10070)
[2025-07-28T14:27:59.620+0000] {local_task_job_runner.py:228} INFO - Task exited with return code 1
[2025-07-28T14:27:59.748+0000] {taskinstance.py:2778} INFO - 0 downstream tasks scheduled from follow-on schedule check
