[2025-07-23T19:12:48.114+0000] {taskinstance.py:1159} INFO - Dependencies all met for dep_context=non-requeueable deps ti=<TaskInstance: orders_dag.fetch_and_load_orders manual__2025-07-23T19:12:45.369699+00:00 [queued]>
[2025-07-23T19:12:48.130+0000] {taskinstance.py:1159} INFO - Dependencies all met for dep_context=requeueable deps ti=<TaskInstance: orders_dag.fetch_and_load_orders manual__2025-07-23T19:12:45.369699+00:00 [queued]>
[2025-07-23T19:12:48.131+0000] {taskinstance.py:1361} INFO - Starting attempt 1 of 1
[2025-07-23T19:12:48.151+0000] {taskinstance.py:1382} INFO - Executing <Task(PythonOperator): fetch_and_load_orders> on 2025-07-23 19:12:45.369699+00:00
[2025-07-23T19:12:48.167+0000] {standard_task_runner.py:57} INFO - Started process 28984 to run task
[2025-07-23T19:12:48.182+0000] {standard_task_runner.py:84} INFO - Running: ['***', 'tasks', 'run', 'orders_dag', 'fetch_and_load_orders', 'manual__2025-07-23T19:12:45.369699+00:00', '--job-id', '4', '--raw', '--subdir', 'DAGS_FOLDER/orders_dag.py', '--cfg-path', '/tmp/tmpcdrcutro']
[2025-07-23T19:12:48.188+0000] {standard_task_runner.py:85} INFO - Job 4: Subtask fetch_and_load_orders
[2025-07-23T19:12:48.339+0000] {task_command.py:416} INFO - Running <TaskInstance: orders_dag.fetch_and_load_orders manual__2025-07-23T19:12:45.369699+00:00 [running]> on host 0107f91018e2
[2025-07-23T19:12:48.466+0000] {taskinstance.py:1662} INFO - Exporting env vars: AIRFLOW_CTX_DAG_OWNER='***' AIRFLOW_CTX_DAG_ID='orders_dag' AIRFLOW_CTX_TASK_ID='fetch_and_load_orders' AIRFLOW_CTX_EXECUTION_DATE='2025-07-23T19:12:45.369699+00:00' AIRFLOW_CTX_TRY_NUMBER='1' AIRFLOW_CTX_DAG_RUN_ID='manual__2025-07-23T19:12:45.369699+00:00'
[2025-07-23T19:12:48.675+0000] {taskinstance.py:1937} ERROR - Task failed with exception
Traceback (most recent call last):
  File "/home/airflow/.local/lib/python3.8/site-packages/requests/models.py", line 971, in json
    return complexjson.loads(self.text, **kwargs)
  File "/usr/local/lib/python3.8/json/__init__.py", line 357, in loads
    return _default_decoder.decode(s)
  File "/usr/local/lib/python3.8/json/decoder.py", line 337, in decode
    obj, end = self.raw_decode(s, idx=_w(s, 0).end())
  File "/usr/local/lib/python3.8/json/decoder.py", line 355, in raw_decode
    raise JSONDecodeError("Expecting value", s, err.value) from None
json.decoder.JSONDecodeError: Expecting value: line 1 column 1 (char 0)

During handling of the above exception, another exception occurred:

Traceback (most recent call last):
  File "/home/airflow/.local/lib/python3.8/site-packages/airflow/operators/python.py", line 192, in execute
    return_value = self.execute_callable()
  File "/home/airflow/.local/lib/python3.8/site-packages/airflow/operators/python.py", line 209, in execute_callable
    return self.python_callable(*self.op_args, **self.op_kwargs)
  File "/opt/airflow/dags/orders_dag.py", line 23, in fetch_and_load_orders
    data = response.json()
  File "/home/airflow/.local/lib/python3.8/site-packages/requests/models.py", line 975, in json
    raise RequestsJSONDecodeError(e.msg, e.doc, e.pos)
requests.exceptions.JSONDecodeError: Expecting value: line 1 column 1 (char 0)
[2025-07-23T19:12:48.694+0000] {taskinstance.py:1400} INFO - Marking task as FAILED. dag_id=orders_dag, task_id=fetch_and_load_orders, execution_date=20250723T191245, start_date=20250723T191248, end_date=20250723T191248
[2025-07-23T19:12:48.717+0000] {standard_task_runner.py:104} ERROR - Failed to execute job 4 for task fetch_and_load_orders (Expecting value: line 1 column 1 (char 0); 28984)
[2025-07-23T19:12:48.763+0000] {local_task_job_runner.py:228} INFO - Task exited with return code 1
[2025-07-23T19:12:48.796+0000] {taskinstance.py:2778} INFO - 0 downstream tasks scheduled from follow-on schedule check
